<?xml version="1.0" encoding="utf-8"?>
<!-- This URDF was automatically created by SolidWorks to URDF Exporter! Originally created by Stephen Brawner (brawner@gmail.com) 
     Commit Version: 1.6.0-4-g7f85cfe  Build Version: 1.6.7995.38578
     For more information, please see http://wiki.ros.org/sw_urdf_exporter -->
<robot
  name="final3">
    <!-- KDL-safe root -->
  <link name="world_dummy"/>
  <joint name="world_to_stand" type="fixed">
    <parent link="world_dummy"/>
    <child  link="base_stand"/>
  </joint>

   <!-- base_stand -->
  <link name="base_stand">
    <inertial>
      <origin xyz="0 0 0" rpy="0 0 0"/>
      <mass value="15.0"/>
      <inertia ixx="0.2045" iyy="0.2045" izz="0.4000" ixy="0" ixz="0" iyz="0"/>
    </inertial>
    <visual>
      <origin xyz="0 0 -0.03" rpy="0 0 0"/>
      <geometry><box size="0.40 0.40 0.06"/></geometry>
      <material name="stand_gray"><color rgba="0.7 0.7 0.7 1"/></material>
    </visual>
  </link>

  <joint name="base_stand_fix" type="fixed">
    <origin xyz="0 0 0" rpy="0 0 0"/>
    <parent link="base_stand"/>
    <child  link="base_link"/>
  </joint>


  <link
    name="base_link">
    <inertial>
      <origin
        xyz="-0.00336427008800971 0 0.176177481833415"
        rpy="0 0 0" />
      <mass
        value="1.13227805038393" />
      <inertia
        ixx="0.0121531021222289"
        ixy="-3.59019259225343E-19"
        ixz="0.000587859098098468"
        iyy="0.0119525756112575"
        iyz="-2.78003552835926E-18"
        izz="0.00102146038185239" />
    </inertial>
    <visual>
      <origin
        xyz="0 0 0"
        rpy="0 0 0" />
      <geometry>
        <mesh
          filename="package://final3/meshes/base_link.STL" />
      </geometry>
      <material
        name="">
        <color
          rgba="0.792156862745098 0.819607843137255 0.933333333333333 1" />
      </material>
    </visual>
    <collision>
      <origin
        xyz="0 0 0"
        rpy="0 0 0" />
      <geometry>
        <mesh
          filename="package://final3/meshes/base_link.STL" />
      </geometry>
    </collision>
  </link>
  <link
    name="l1">
    <inertial>
      <origin
        xyz="-0.189428590016577 -0.064162366573651 5.55111512312578E-17"
        rpy="0 0 0" />
      <mass
        value="1.3016523193261" />
      <inertia
        ixx="0.00219848452395246"
        ixy="-0.00342968551632687"
        ixz="4.82758823424816E-18"
        iyy="0.011162366813926"
        iyz="1.70485902643459E-18"
        izz="0.0116571619649917" />
    </inertial>
    <visual>
      <origin
        xyz="0 0 0"
        rpy="0 0 0" />
      <geometry>
        <mesh
          filename="package://final3/meshes/l1.STL" />
      </geometry>
      <material
        name="">
        <color
          rgba="0.792156862745098 0.819607843137255 0.933333333333333 1" />
      </material>
    </visual>
    <collision>
      <origin
        xyz="0 0 0"
        rpy="0 0 0" />
      <geometry>
        <mesh
          filename="package://final3/meshes/l1.STL" />
      </geometry>
    </collision>
  </link>
  <joint
    name="j1"
    type="revolute">
    <origin
      xyz="-0.065 0 0.278"
      rpy="0 0 0" />
    <parent
      link="base_link" />
    <child
      link="l1" />
    <axis
      xyz="0 0 -1" />
    <limit lower="-1.57" upper="1.57" effort="50" velocity="1.5"/>
    <dynamics damping="0.0" friction="0.0"/>
  </joint>
  <link
    name="l2">
    <inertial>
      <origin
        xyz="-0.323439138443078 0.0292504033924335 0.0100322732874896"
        rpy="0 0 0" />
      <mass
        value="3.6875217386648" />
      <inertia
        ixx="0.0014809901425467"
        ixy="0.00089641488545978"
        ixz="-1.00733265699137E-07"
        iyy="0.0114085095981645"
        iyz="5.98503904057003E-07"
        izz="0.0120439794121417" />
    </inertial>
    <visual>
      <origin
        xyz="0 0 0"
        rpy="0 0 0" />
      <geometry>
        <mesh
          filename="package://final3/meshes/l2.STL" />
      </geometry>
      <material
        name="">
        <color
          rgba="0.792156862745098 0.819607843137255 0.933333333333333 1" />
      </material>
    </visual>
    <collision>
      <origin
        xyz="0 0 0"
        rpy="0 0 0" />
      <geometry>
        <mesh
          filename="package://final3/meshes/l2.STL" />
      </geometry>
    </collision>
  </link>
  <joint
    name="j2"
    type="revolute">
    <origin
      xyz="-0.37876 -0.12724 -0.0935"
      rpy="0 0 0" />
    <parent
      link="l1" />
    <child
      link="l2" />
    <axis
      xyz="0 0 1" />
    <limit lower="-3.14" upper="3.14" effort="30" velocity="1.0"/>
    <dynamics damping="0.0" friction="0.0"/>
  </joint>
  <link
    name="pitch">
    <inertial>
      <origin
        xyz="-9.658E-05 -0.0010798 -5.4956E-15"
        rpy="0 0 0" />
      <mass
        value="0.0022646" />
      <inertia
        ixx="3.2092E-08"
        ixy="7.6869E-14"
        ixz="4.9764E-15"
        iyy="3.2093E-08"
        iyz="4.1593E-15"
        izz="4.6816E-08" />
    </inertial>
    <visual>
      <origin
        xyz="0 0 0"
        rpy="0 0 0" />
      <geometry>
        <mesh
          filename="package://final3/meshes/pitch.STL" />
      </geometry>
      <material
        name="">
        <color
          rgba="0.89804 0.91765 0.92941 1" />
      </material>
    </visual>
    <collision>
      <origin
        xyz="0 0 0"
        rpy="0 0 0" />
      <geometry>
        <mesh
          filename="package://final3/meshes/pitch.STL" />
      </geometry>
    </collision>
  </link>
  <joint
    name="pitch_j"
    type="revolute">
    <origin
      xyz="-0.39841 0.035635 0.0875"
      rpy="0 0 0" />
    <parent
      link="l2" />
    <child
      link="pitch" />
    <axis
      xyz="-0.99602 0.089087 0" />
    <limit lower="-0.6" upper="0.6" effort="25" velocity="1.5"/>
  </joint>
  <link
    name="roll">
    <inertial>
      <origin
        xyz="-2.3765E-09 -3.7085E-08 0.049659"
        rpy="0 0 0" />
      <mass
        value="0.014628" />
      <inertia
        ixx="4.8925E-06"
        ixy="-2.8915E-09"
        ixz="-1.7932E-13"
        iyy="4.8604E-06"
        iyz="-2.5938E-12"
        izz="3.3066E-07" />
    </inertial>
    <visual>
      <origin
        xyz="0 0 0"
        rpy="0 0 0" />
      <geometry>
        <mesh
          filename="package://final3/meshes/roll.STL" />
      </geometry>
      <material
        name="">
        <color
          rgba="0.89804 0.91765 0.92941 1" />
      </material>
    </visual>
    <collision>
      <origin
        xyz="0 0 0"
        rpy="0 0 0" />
      <geometry>
        <mesh
          filename="package://final3/meshes/roll.STL" />
      </geometry>
    </collision>
  </link>
  <joint
    name="roll_j"
    type="revolute">
    <origin
      xyz="-9.658E-05 -0.0010798 0"
      rpy="0 0 0" />
    <parent
      link="pitch" />
    <child
      link="roll" />
    <axis
      xyz="-0.089087 -0.99602 0" />
    <limit lower="-0.6" upper="0.6" effort="25" velocity="1.5"/>
  </joint>
</robot>